#VRML_SIM R2025a utf8
# A modular differential-drive mobile robot designed for research and teaching in robotics.
# HamBot includes support for visual sensors, lidar, inertial measurement, onboard computation, and display.
#
# Features:
# - Two motorized wheels with encoders and adjustable torque/velocity
# - Modular sensor components (camera, lidar, IMU, display) defined as external PROTOs
# - Support for a Raspberry Pi board model and external device integration
# - Multiple predefined appearances using Webots' built-in PBR and classic materials
# - Caster wheels and bounding object for realistic ground interaction
# - Compatible with physics simulation and full sensor interfacing
# author: Chance J. Hamilton


EXTERNPROTO "https://raw.githubusercontent.com/cyberbotics/webots/R2025a/projects/appearances/protos/GlossyPaint.proto"
EXTERNPROTO "https://raw.githubusercontent.com/cyberbotics/webots/R2025a/projects/appearances/protos/Rubber.proto"
EXTERNPROTO "https://raw.githubusercontent.com/cyberbotics/webots/R2025a/projects/appearances/protos/Plastic.proto"
EXTERNPROTO "https://raw.githubusercontent.com/cyberbotics/webots/R2025a/projects/appearances/protos/BrushedAluminium.proto"
EXTERNPROTO "https://raw.githubusercontent.com/cyberbotics/webots/R2025a/projects/appearances/protos/Pcb.proto"
EXTERNPROTO "https://raw.githubusercontent.com/cyberbotics/webots/R2025a/projects/appearances/protos/ScuffedPlastic.proto"
EXTERNPROTO "IMUComponent.proto"
EXTERNPROTO "DisplayComponent.proto"
EXTERNPROTO "CameraComponent.proto"
EXTERNPROTO "RPiComponent.proto"
EXTERNPROTO "LidarComponent.proto"

PROTO HamBot [
  field  SFVec3f     translation     0 0 0
  field  SFRotation  rotation        0 0 1 1.57
  field  SFString    name            "HamBot"
  field  SFString    controller      "hambot_controller"
  field  MFString    controllerArgs  []
  field  SFString    customData      ""
  field  SFBool      supervisor      TRUE
  field  SFBool      synchronization TRUE
  field  SFBool      selfCollision   FALSE
]
{
  Robot {
    translation IS translation
    rotation IS rotation
    name IS name
    controller IS controller
    controllerArgs IS controllerArgs
    customData IS customData
    supervisor IS supervisor
    synchronization IS synchronization
    selfCollision IS selfCollision
    children [

      # Visual body mesh
      DEF MAIN_BODY Pose {
        translation 0.000000 0.000000 0
        rotation 0.000000 0.000000 1.000000 1.57
        children [
          Shape {
            appearance Plastic {
              colorOverride 0.004 0.196 0.078
              type  "rough"
            }
            geometry Mesh {
              url "models/Body/bottom_layer.obj"
            }
          }
          Shape {
            castShadows FALSE
            appearance Plastic {
              colorOverride 0.004 0.196 0.078
              type  "rough"
            }
            geometry Mesh {
              url "models/Body/top_layer.obj"
            }
          }
          Shape {
            appearance Plastic {
              colorOverride 0.004 0.196 0.078
              type  "rough"
            }
            geometry Mesh {
              url "models/Body/battery_slot.obj"
            }
          }
          Shape {
            appearance BrushedAluminium {
              colorOverride 1.0 0.843 0.0
            }
            geometry Mesh {
              url "models/Body/chassis_pillar_1.obj"
            }
          }
          Shape {
            appearance BrushedAluminium {
              colorOverride 1.0 0.843 0.0
            }
            geometry Mesh {
              url "models/Body/chassis_pillar_2.obj"
            }
          }
          Shape {
            appearance BrushedAluminium {
              colorOverride 1.0 0.843 0.0
            }
            geometry Mesh {
              url "models/Body/chassis_pillar_3.obj"
            }
          }
          Shape {
            appearance BrushedAluminium {
              colorOverride 1.0 0.843 0.0
            }
            geometry Mesh {
              url "models/Body/chassis_pillar_4.obj"
            }
          }
          Shape {
            appearance BrushedAluminium {
              colorOverride 1.0 0.843 0.0
            }
            geometry Mesh {
              url "models/Body/RPI_pillar_1.obj"
            }
          }
          Shape {
            appearance BrushedAluminium {
              colorOverride 1.0 0.843 0.0
            }
            geometry Mesh {
              url "models/Body/RPI_pillar_2.obj"
            }
          }
          Shape {
            appearance BrushedAluminium {
              colorOverride 1.0 0.843 0.0
            }
            geometry Mesh {
              url "models/Body/RPI_pillar_3.obj"
            }
          }
          Shape {
            appearance BrushedAluminium {
              colorOverride 1.0 0.843 0.0
            }
            geometry Mesh {
              url "models/Body/RPI_pillar_4.obj"
            }
          }
          Shape {
            appearance BrushedAluminium {
              colorOverride 0.0 0.0 0.0
            }
            geometry Mesh {
              url "models/Body/caster_1.obj"
            }
          }
          Shape {
            appearance BrushedAluminium {
              colorOverride 0.0 0.0 0.0
            }
            geometry Mesh {
              url "models/Body/caster_2.obj"
            }
          }


          Shape {
            appearance ScuffedPlastic {
              colorOverride 1.0 1.0 1.0
            }
            geometry Mesh {
              url "models/Body/motor_l.obj"
            }
          }
          Shape {
            appearance ScuffedPlastic {
              colorOverride 1.0 1.0 1.0
            }
            geometry Mesh {
              url "models/Body/motor_r.obj"
            }
          }
          Shape {
            appearance ScuffedPlastic {
              colorOverride 0.004 0.196 0.078
            }
            geometry Mesh {
              url "models/Body/hub_l.obj"
            }
          }
          Shape {
            appearance ScuffedPlastic {
              colorOverride 0.004 0.196 0.078
            }
            geometry Mesh {
              url "models/Body/hub_r.obj"
            }
          }
          Shape {
            appearance ScuffedPlastic {
              colorOverride 0.0 0.0 0.0
            }
            geometry Mesh {
              url "models/Body/battery.obj"
            }
          }
          IMUComponent {
            translation 0.0 0.0 0.0
            rotation 1 0 0 0
          }
          DisplayComponent{
            translation 0.0 0.0 0.0
            rotation 1 0 0 0
          }
          CameraComponent{
            translation 0.0 0.0 0.0
            rotation 1 0 0 0
          }
          RPiComponent{
            translation 0.0 0.0 0.0
            rotation 1 0 0 0
          }
          LidarComponent{
            translation 0.0 0.0 0.0
            rotation 1 0 0 0
          }
        ]
      }
      # Left Wheel
      HingeJoint {
        jointParameters HingeJointParameters {
          axis 0.000000 1.000000 0.000000
          anchor 0.0 0.0 0.012
          dampingConstant 5.0
          staticFriction 1.0
        }
        device [
          RotationalMotor {
            name "left motor"
            maxVelocity 18
            maxTorque 100
          }
          PositionSensor {
            name "left wheel encoder"
          }
        ]
        endPoint Solid {
          translation 0.0 0.00000 0.00
          rotation 0.000000 0.000000 1.000000 1.57
          children [
            Pose {
              translation 0.0900 -0.00011 0.012
              rotation 0.000000 0.000000 1.000000 3.14
              children [
                DEF RIM_AND_TIRE_SHAPES Group {
                  children [
                    DEF TIRE_SHAPE Shape {
                      appearance Rubber {
                        type "flat"
                      }
                      geometry Mesh {
                        url "models/Body/Wheel.obj"
                      }
                    }
                  ]
                }
              ]
            }
          ]
          name "left wheel"
          boundingObject DEF LEFT_WHEEL_CYLINDER Pose {
            translation 0.0900 -0.00011 0.012
            rotation 0.000000 1.000000 0.000000 1.57
            children [
              DEF WHEEL_CYLINDER Cylinder {
                height 0.01
                radius 0.045
              }
            ]
          }
          physics DEF WHEEL_PHYSICS Physics {
            density -1
            mass 0.0005
          }
        }
      }
      # Right Wheel
      HingeJoint {
        jointParameters HingeJointParameters {
          axis 0.000000 1.000000 0.000000
          anchor 0.0 0.0 0.012
          dampingConstant 5.0
          staticFriction 1.0
        }
        device [
          RotationalMotor {
            name "right motor"
            maxVelocity 18
            maxTorque 100
          }
          PositionSensor {
            name "right wheel encoder"
          }
        ]
        endPoint Solid {
          translation 0.0 0.00000 0.00
          rotation 0.000000 0.000000 1.000000 1.57
          children [
            Pose {
              translation -0.0900 -0.00011 0.012
              rotation 0.000000 0.000000 1.000000 0.0
              children [
                DEF RIM_AND_TIRE_SHAPES Group {
                  children [
                    DEF TIRE_SHAPE Shape {
                      appearance Rubber {
                        type "flat"
                      }
                      geometry Mesh {
                        url "models/Body/Wheel.obj"
                      }
                    }
                  ]
                }
              ]
            }
          ]
          name "right wheel"
          boundingObject DEF RIGHT_WHEEL_CYLINDER Pose {
            translation -0.0900 -0.00011 0.012
            rotation 0.000000 1.000000 0.000000 1.57
            children [
              DEF WHEEL_CYLINDER Cylinder {
                height 0.01
                radius 0.045
              }
            ]
          }
          physics DEF WHEEL_PHYSICS Physics {
            density -1
            mass 0.0005
          }
        }
      }
      InertialUnit {
        translation 0.0 0.0 0.00
        rotation 0.000000 0.000000 1.000000 0
        name "imu"
      }
      Camera {
        translation           0.079 0.0 0.08
        rotation              0 0 1 0
        name                  "camera"
        fieldOfView           0.7854
        width                 640
        height                480
        recognitionColors [
          1 0 0,
          0 1 0,
          0 0 1,
          1 1 0
        ]
        recognition Recognition {
        }
      }
      Lidar {
        translation 0 0 .13
        name "lidar"
        fieldOfView 6.283184
        horizontalResolution 360
        numberOfLayers 1
        near 0.05
        defaultFrequency 12
        minRange 0.0700000
        maxRange 3.000000
        noise 0.000833
        resolution -1
        type "rotating"
      }
      GPS {
        name "gps"
      }
      Display {
        width 64
        height 64
        name "User Display"
      }

      DEF CASTER_JOINT_REAR BallJoint {
        jointParameters BallJointParameters {
          anchor -0.063 -0.001 -0.021
        }
        endPoint Solid {
          name "Front"
          translation -0.063 -0.001 -0.021
          children [
            Shape {

              appearance PBRAppearance {
              }
              geometry DEF CASTER_SPHERE_REAR Sphere {
                radius 0.0109
                subdivision 2
              }
            }
          ]
          boundingObject USE CASTER_SPHERE_REAR
          physics Physics {
          }
        }
      }
      DEF CASTER_JOINT_FRONT BallJoint {
        jointParameters BallJointParameters {
          anchor 0.0635 -0.000 -0.021
        }
        endPoint Solid {

          translation 0.0635 -0.000 -0.021
          children [
            Shape {
              appearance PBRAppearance {
              }
              geometry DEF CASTER_SPHERE_FRONT Sphere {
                radius 0.0109
                subdivision 2
              }
            }
          ]
          boundingObject USE CASTER_SPHERE_FRONT
          physics Physics {
          }
        }
      }
    ]

    boundingObject Group {
      children [
        Pose {
          translation 0.0 0.0 0.056
          children [
            Box {
              size 0.15 0.14 0.171
            }
          ]
        }
      ]
    }
    physics Physics {
      density -1
      mass 0.2260000
    }
  }
}
